Cwd: /volumes/erweiterung/Entwicklung/Cygwin/2021/bughunting-02.git
Command: python reproduce.py

Traceback (most recent call last):
  File "/volumes/erweiterung/Entwicklung/Cygwin/2021/bughunting-02.git/virtualenv/2021-10-21_0918/lib/python3.8/site-packages/PIL/ImageTk.py", line 176, in paste
    tk.call("PyImagingPhoto", self.__photo, block.id)
_tkinter.TclError: invalid command name "PyImagingPhoto"

During handling of the above exception, another exception occurred:

Traceback (most recent call last):
  File "reproduce.py", line 13, in <module>
    photoimage = ImageTk.PhotoImage(image)
  File "/volumes/erweiterung/Entwicklung/Cygwin/2021/bughunting-02.git/virtualenv/2021-10-21_0918/lib/python3.8/site-packages/PIL/ImageTk.py", line 115, in __init__
    self.paste(image)
  File "/volumes/erweiterung/Entwicklung/Cygwin/2021/bughunting-02.git/virtualenv/2021-10-21_0918/lib/python3.8/site-packages/PIL/ImageTk.py", line 180, in paste
    from . import _imagingtk
RuntimeError: No such process
